Workbook

Sheet Instructions
A1: Palm Listed Companies — Long List Template
A2: Annual report → standardized long list with auto-scoring & validation
A4: 1. Raw Data Management
A5: Raw_Extract | B5: Every fact extracted from the annual report goes here first. One row = one data point.
A6: ├ Required fields | B6: Company / Source File / Page / Field Name / Extracted Value / Unit / Evidence Quote
A7: ├ Audit trail | B7: Extracted By / Date / Method (Manual·AI·OCR) / Reviewed By / Date
A8: └ Confidence | B8: High / Medium / Low — Low automatically flagged in Validation_Flags
A10: 2. Output Generation
A11: Company_Master | B11: Company-level qualitative info (HQ, ownership, deal thoughts, red flags).
A12: Asset_Operations | B12: Land, mills, production volumes. [auto] columns auto-calculate yield/OER/KER.
A13: Financials | B13: P&L, B/S, CF, market data. [auto] columns auto-calculate Net Debt, NWC, FCF, ratios.
A15: 3. Screening & Scoring
A16: Screening | B16: Pulls KPIs from 3 source sheets via XLOOKUP. 9 score columns auto-generated.
A17: Scoring_Criteria | B17: Threshold table — edit blue cells (D5:H13) to recalibrate all scores instantly.
A18: ├ Auto scores | B18: Scale, Asset Quality, Integration, Op Eff, Profit, Leverage, Liquidity (X~AD)
A19: ├ Manual scores | B19: ESG & Legality, Dealability (AE, AF) — enter 1~5 directly
A20: └ Total Score | B20: Simple average of all 9 scores (AG)
A22: 4. Validation
A23: Validation_Flags | B23: Manual issue log (rows 2~50) + automated rule output (rows 62+).
A24: └ Auto rules | B24: 11 rules: area sums, OER range/definition, Net Debt sign, B/S balance, EBITDA logic, EBITDA reported-vs-calculated, Net Debt reported-vs-calculated, Low confidence, etc.
A26: Color Conventions
A27: Blue text | B27: Manual input — value typed by analyst from the annual report
A28: Black text | B28: Formula — auto-calculated within the same sheet
A29: Green text | B29: Cross-sheet link — pulled from another sheet via XLOOKUP
A30: Yellow fill | B30: Key output (Total Score) — review before final ranking
A31: [auto] header | B31: Column is calculated; do not overwrite the formula
A33: Unit Conventions
A34: Land | B34: hectares (ha)
A35: Production | B35: tonnes (t); capacities in tph or tpa as headed
A36: Prices | B36: local currency per kg
A37: Financials | B37: IDR billion (bn) — convert if source is mn or USD
A38: Ratios | B38: decimal (0.25 = 25%) — formatted as % automatically
A40: Business Model Notes (P7)
A41: Upstream | B41: Plantation only (FFB → CPO). Apply all 9 scores fully.
A42: Integrated | B42: Plantation + downstream (e.g., AALI). Apply all 9 scores fully.
A43: Downstream | B43: Refining only (e.g., CBUT). Plantation-based scores (Scale, Asset Quality, Op Eff) will return blank — Total Score auto-excludes blank scores via AVERAGE.
A44: Other | B44: Trading, services, or hybrid. Use manual qualitative notes.
A46: Per-PDF Workflow (v1 update)
A47: Usage | B47: This template is intended to be copied PER annual report PDF. Each filled copy represents one company × one report year (one row in Company_Master, Asset_Operations, Financials).
A48: File Naming | B48: Save each filled copy in the relevant company folder as {TICKER}_{YEAR}_longlist.xlsx.
...

Sheet Raw_Extract
A1: Company | B1: Source File | C1: Report Year | D1: Field Group | E1: Field Name | F1: Extracted Value | G1: Unit | H1: Page | I1: Evidence Quote | J1: Confidence | K1: Normalization Note | L1: Validation Flag | M1: Extracted By | N1: Extracted Date | O1: Method | P1: Reviewed By | Q1: Reviewed Date
A2: PT Astra Agro Lestari Tbk | B2: AALI_2023_AR.pdf | C2: 2023 | D2: Company | E2: Company Name | F2: PT Astra Agro Lestari Tbk | G2: text | H2: 1 | I2: Cover | J2: High | M2: LLM | N2: 2026-04-18 | O2: AI
A3: PT Astra Agro Lestari Tbk | B3: AALI_2023_AR.pdf | C3: 2023 | D3: Company | E3: Ticker | F3: AALI | G3: text | I3: Filename | J3: High | M3: LLM | N3: 2026-04-18 | O3: AI
A4: PT Astra Agro Lestari Tbk | B4: AALI_2023_AR.pdf | C4: 2023 | D4: Company | E4: Report Year | F4: 2023 | G4: year | I4: Filename | J4: High | M4: LLM | N4: 2026-04-18 | O4: AI
A5: PT Astra Agro Lestari Tbk | B5: AALI_2023_AR.pdf | C5: 2023 | D5: Financial | E5: Revenue | F5: 20745 | G5: IDR bn | H5: 10 | I5: Pendapatan Bersih 20,745 (2023), Rp miliar (confirmed by p11 label) | J5: High | M5: LLM | N5: 2026-04-18 | O5: AI
A6: PT Astra Agro Lestari Tbk | B6: AALI_2023_AR.pdf | C6: 2023 | D6: Financial | E6: Gross Profit | F6: 2771 | G6: IDR bn | H6: 10 | I6: Laba Bruto 2,771 | J6: High | M6: LLM | N6: 2026-04-18 | O6: AI
A7: PT Astra Agro Lestari Tbk | B7: AALI_2023_AR.pdf | C7: 2023 | D7: Financial | E7: Net Profit | F7: 1088 | G7: IDR bn | H7: 10 | I7: Laba Tahun Berjalan 1,088 | J7: High | M7: LLM | N7: 2026-04-18 | O7: AI
A8: PT Astra Agro Lestari Tbk | B8: AALI_2023_AR.pdf | C8: 2023 | D8: Financial | E8: Profit Attributable to Parent | F8: 1056 | G8: IDR bn | H8: 10 | I8: - Pemilik Entitas Induk 1,056 | J8: High | M8: LLM | N8: 2026-04-18 | O8: AI
A9: PT Astra Agro Lestari Tbk | B9: AALI_2023_AR.pdf | C9: 2023 | D9: Financial | E9: Total Comprehensive Income | F9: 1136 | G9: IDR bn | H9: 10 | I9: Penghasilan Komprehensif Tahun Berjalan 1,136 | J9: High | M9: LLM | N9: 2026-04-18 | O9: AI
A10: PT Astra Agro Lestari Tbk | B10: AALI_2023_AR.pdf | C10: 2023 | D10: Financial | E10: Current Assets | F10: 7118 | G10: IDR bn | H10: 10 | I10: Aset Lancar 7,118 | J10: High | M10: LLM | N10: 2026-04-18 | O10: AI
A11: PT Astra Agro Lestari Tbk | B11: AALI_2023_AR.pdf | C11: 2023 | D11: Financial | E11: Non-Current Assets | F11: 21728 | G11: IDR bn | H11: 10 | I11: Aset Tidak Lancar 21,728 | J11: High | M11: LLM | N11: 2026-04-18 | O11: AI
A12: PT Astra Agro Lestari Tbk | B12: AALI_2023_AR.pdf | C12: 2023 | D12: Financial | E12: Total Assets | F12: 28846 | G12: IDR bn | H12: 10 | I12: Total Aset 28,846 | J12: High | M12: LLM | N12: 2026-04-18 | O12: AI
A13: PT Astra Agro Lestari Tbk | B13: AALI_2023_AR.pdf | C13: 2023 | D13: Financial | E13: Current Liabilities | F13: 3882 | G13: IDR bn | H13: 10 | I13: Liabilitas Jangka Pendek 3,882 | J13: High | M13: LLM | N13: 2026-04-18 | O13: AI
A14: PT Astra Agro Lestari Tbk | B14: AALI_2023_AR.pdf | C14: 2023 | D14: Financial | E14: Long-Term Liabilities | F14: 2398 | G14: IDR bn | H14: 10 | I14: Liabilitas Jangka Panjang 2,398 | J14: High | M14: LLM | N14: 2026-04-18 | O14: AI
A15: PT Astra Agro Lestari Tbk | B15: AALI_2023_AR.pdf | C15: 2023 | D15: Financial | E15: Total Liabilities | F15: 6280 | G15: IDR bn | H15: 10 | I15: Total Liabilitas 6,280 | J15: High | M15: LLM | N15: 2026-04-18 | O15: AI
A16: PT Astra Agro Lestari Tbk | B16: AALI_2023_AR.pdf | C16: 2023 | D16: Financial | E16: Total Equity | F16: 22566 | G16: IDR bn | H16: 10 | I16: Total Ekuitas 22,566 | J16: High | M16: LLM | N16: 2026-04-18 | O16: AI
... A67: PT Astra Agro Lestari Tbk | B67: AALI_2023_AR.pdf | C67: 2023 | D67: Operation | E67: CPO Sales Volume | F67: 2345000 | G67: t | H67: 14 | I67: Volume Penjualan CPO dan Turunannya 2,345 ribu ton | J67: High | M67: LLM | N67: 2026-04-18 | O67: AI
A68: PT Astra Agro Lestari Tbk | B68: AALI_2024_AR.pdf | C68: 2024 | D68: Company | E68: Company Name | F68: PT Astra Agro Lestari Tbk | G68: text | H68: 12 | I68: Laporan Tahunan 2024 - PT Astra Agro Lestari Tbk | J68: High | M68: LLM | N68: 2026-04-18 | O68: AI
A69: PT Astra Agro Lestari Tbk | B69: AALI_2024_AR.pdf | C69: 2024 | D69: Company | E69: Controlling Shareholder | F69: PT Astra International Tbk 79.68% | G69: % | H69: 83 | I69: PT Astra International Tbk 1,533,682,440 79.68% | J69: High | M69: LLM | N69: 2026-04-18 | O69: AI
A70: PT Astra Agro Lestari Tbk | B70: AALI_2024_AR.pdf | C70: 2024 | D70: Company | E70: Public Float | F70: 0.2032 | G70: % | H70: 83 | I70: Masyarakat Lainnya (masing-masing di bawah 5%) 391,005,893 20.32% | J70: High | M70: LLM | N70: 2026-04-18 | O70: AI
A71: PT Astra Agro Lestari Tbk | B71: AALI_2024_AR.pdf | C71: 2024 | D71: Financial | E71: Revenue (Net) | F71: 21815 | G71: IDR bn | H71: 12 | I71: Pendapatan Bersih 21,815 20,745 21,829 | J71: High | M71: LLM | N71: 2026-04-18 | O71: AI
A72: PT Astra Agro Lestari Tbk | B72: AALI_2024_AR.pdf | C72: 2024 | D72: Financial | E72: Gross Profit | F72: 3341 | G72: IDR bn | H72: 12 | I72: Laba Bruto 3,341 2,771 3,822 | J72: High | M72: LLM | N72: 2026-04-18 | O72: AI
A73: PT Astra Agro Lestari Tbk | B73: AALI_2024_AR.pdf | C73: 2024 | D73: Financial | E73: Cost of Revenue | F73: 18474 | G73: IDR bn | H73: 108 | I73: Beban Pokok Pendapatan (18,474.41) (17,974.49) | J73: High | M73: LLM | N73: 2026-04-18 | O73: AI
A74: PT Astra Agro Lestari Tbk | B74: AALI_2024_AR.pdf | C74: 2024 | D74: Financial | E74: Operating Expense | F74: 1682 | G74: IDR bn | H74: 108 | I74: Beban Usaha (1,682.14) (1,519.77) | J74: High | M74: LLM | N74: 2026-04-18 | O74: AI
A75: PT Astra Agro Lestari Tbk | B75: AALI_2024_AR.pdf | C75: 2024 | D75: Financial | E75: EBIT (Gross Profit - OpEx) | F75: 1658 | G75: IDR bn | H75: 108 | I75: Calculated: Gross Profit 3,340.62 - OpEx 1,682.14 = 1,658.48 | J75: Medium | M75: LLM | N75: 2026-04-18 | O75: AI
A76: PT Astra Agro Lestari Tbk | B76: AALI_2024_AR.pdf | C76: 2024 | D76: Financial | E76: Finance Cost | F76: 265 | G76: IDR bn | H76: 108 | I76: Biaya Pendanaan (264.69) (268.26) | J76: High | M76: LLM | N76: 2026-04-18 | O76: AI
A77: PT Astra Agro Lestari Tbk | B77: AALI_2024_AR.pdf | C77: 2024 | D77: Financial | E77: Profit Before Income Tax | F77: 1707 | G77: IDR bn | H77: 108 | I77: Laba Sebelum Pajak Penghasilan 1,707.13 1,498.40 | J77: High | M77: LLM | N77: 2026-04-18 | O77: AI
A78: PT Astra Agro Lestari Tbk | B78: AALI_2024_AR.pdf | C78: 2024 | D78: Financial | E78: Net Profit | F78: 1187 | G78: IDR bn | H78: 12 | I78: Laba Tahun Berjalan 1,187 1,088 | J78: High | M78: LLM | N78: 2026-04-18 | O78: AI
A79: PT Astra Agro Lestari Tbk | B79: AALI_2024_AR.pdf | C79: 2024 | D79: Financial | E79: Profit Attributable to Parent | F79: 1148 | G79: IDR bn | H79: 12 | I79: Pemilik Entitas Induk 1,148 1,056 | J79: High | M79: LLM | N79: 2026-04-18 | O79: AI
A80: PT Astra Agro Lestari Tbk | B80: AALI_2024_AR.pdf | C80: 2024 | D80: Financial | E80: Total Assets | F80: 28793 | G80: IDR bn | H80: 12 | I80: Total Aset 28,793 28,846 | J80: High | M80: LLM | N80: 2026-04-18 | O80: AI
A81: PT Astra Agro Lestari Tbk | B81: AALI_2024_AR.pdf | C81: 2024 | D81: Financial | E81: Current Assets | F81: 8434 | G81: IDR bn | H81: 12 | I81: Aset Lancar 8,434 7,118 | J81: High | M81: LLM | N81: 2026-04-18 | O81: AI
... A144: PT Astra Agro Lestari Tbk | B144: AALI_2024_AR.pdf | C144: 2024 | D144: ESG | E144: PROPER Blue Certifications | F144: 26 | G144: count | H144: 105 | I144: Perseroan telah meraih sertifikasi PROPER Biru sebanyak 26 sertifikasi | J144: High | M144: LLM | N144: 2026-04-18 | O144: AI
A145: PT Astra Agro Lestari Tbk | B145: AALI_2025_AR.pdf | C145: 2025 | D145: Company | E145: Company Name | F145: PT Astra Agro Lestari Tbk | G145: text | H145: 15 | I145: Laporan Tahunan 2025 | PT Astra Agro Lestari Tbk | J145: High | M145: LLM | N145: 2026-04-18 | O145: AI
A146: PT Astra Agro Lestari Tbk | B146: AALI_2025_AR.pdf | C146: 2025 | D146: Financial | E146: Revenue (Net) | F146: 28655 | G146: IDR bn | H146: 15 | I146: Pendapatan Bersih 28,655 21,815 | J146: High | M146: LLM | N146: 2026-04-18 | O146: AI
A147: PT Astra Agro Lestari Tbk | B147: AALI_2025_AR.pdf | C147: 2025 | D147: Financial | E147: Cost of Revenue | F147: 24023 | G147: IDR bn | H147: 131 | I147: Beban Pokok Pendapatan (24,023.22) (18,474.41) | J147: High | M147: LLM | N147: 2026-04-18 | O147: AI
A148: PT Astra Agro Lestari Tbk | B148: AALI_2025_AR.pdf | C148: 2025 | D148: Financial | E148: Gross Profit | F148: 4631 | G148: IDR bn | H148: 15 | I148: Laba Bruto 4,631 3,341 | J148: High | M148: LLM | N148: 2026-04-18 | O148: AI
A149: PT Astra Agro Lestari Tbk | B149: AALI_2025_AR.pdf | C149: 2025 | D149: Financial | E149: Operating Expense | F149: 2214 | G149: IDR bn | H149: 131 | I149: Beban Usaha (2,214.37) (1,682.14) | J149: High | M149: LLM | N149: 2026-04-18 | O149: AI
A150: PT Astra Agro Lestari Tbk | B150: AALI_2025_AR.pdf | C150: 2025 | D150: Financial | E150: EBIT (Gross - OpEx) | F150: 2417 | G150: IDR bn | H150: 131 | I150: Calculated: 4,631.43 - 2,214.37 = 2,417.06 | J150: Medium | M150: LLM | N150: 2026-04-18 | O150: AI
A151: PT Astra Agro Lestari Tbk | B151: AALI_2025_AR.pdf | C151: 2025 | D151: Financial | E151: Finance Cost | F151: 139 | G151: IDR bn | H151: 131 | I151: Biaya Pendanaan (139.26) (264.69) | J151: High | M151: LLM | N151: 2026-04-18 | O151: AI
A152: PT Astra Agro Lestari Tbk | B152: AALI_2025_AR.pdf | C152: 2025 | D152: Financial | E152: Interest Income | F152: 280 | G152: IDR bn | H152: 131 | I152: Penghasilan Bunga 279.79 211.50 | J152: High | M152: LLM | N152: 2026-04-18 | O152: AI
...

Sheet Company_Master
A1: Company | B1: Ticker | C1: Exchange | D1: Report Year | E1: Report File | F1: HQ | G1: Country | H1: Core Region | I1: Group Structure Note | J1: Subsidiaries Note | K1: Shareholder Structure Note | L1: Listed Status | M1: Primary Business | N1: Deal Structure Initial Thought | O1: Dealability Note | P1: Acquisition Note | Q1: Key Red Flags | R1: Overall Comment | S1: Business Model [Upstream/Integrated/Downstream]
A2: PT Astra Agro Lestari Tbk | B2: AALI | C2: IDX | D2: 2023 | E2: AALI_2023_AR.pdf | F2: Jakarta, Indonesia | G2: Indonesia | H2: Sumatra/Kalimantan/Sulawesi (diversified) | I2: Part of Astra International group (PT Astra International Tbk parent) | L2: Listed (IDX: AALI) | M2: Palm oil plantation (upstream) + CPO/PKO refining + NPK blending | S2: Integrated
A3: PT Astra Agro Lestari Tbk | B3: AALI | C3: IDX | D3: 2024 | E3: AALI_2024_AR.pdf | F3: Jakarta, Indonesia | G3: Indonesia | H3: Sumatra/Kalimantan/Sulawesi (diversified) | I3: Part of Astra International group (PT Astra International Tbk parent, 79.68% ownership); ultimate controller Jardine Cycle & Carriage / Jardine Matheson. | J3: Multiple oil-palm plantation subsidiaries across Sumatra/Kalimantan/Sulawesi; refinery subsidiaries PT Tanjung Sarana Lestari (TSL, W. Sulawesi) and PT Tanjung Bina Lestari (TBL). | K3: PT Astra International Tbk 79.68%, Public 20.32% (each <5%) | L3: Listed (IDX: AALI) | M3: Palm oil plantation (upstream) + CPO/PKO refining + NPK blending | Q3: FFB production down 14% YoY due to extreme weather and ageing trees (avg age 16.5 yrs, 62% of mature area >15 yrs); third-party FFB availability tight; DMO/DPO export policies affect margins. | R3: Large diversified Indonesian palm producer with refinery and NPK integration. 2024 revenue +5% to Rp21.8 tn; net profit +9% to Rp1.19 tn on stronger CPO prices (+16% avg) offsetting 14% FFB volume decline. Low gearing (<1%). 69% domestic / 31% export sales mix. | S3: Integrated
A4: PT Astra Agro Lestari Tbk | B4: AALI | C4: IDX | D4: 2025 | E4: AALI_2025_AR.pdf | F4: Jakarta, Indonesia | G4: Indonesia | H4: Sumatra/Kalimantan/Sulawesi (diversified) | I4: Part of Astra International group (PT Astra International Tbk parent); ultimate controller Jardine Cycle & Carriage / Jardine Matheson. | J4: Plantation subsidiaries across Sumatra/Kalimantan/Sulawesi; refinery subsidiaries PT Tanjung Sarana Lestari (TSL) and PT Tanjung Bina Lestari (TBL). | K4: PT Astra International Tbk ~79.68% (controlling), Public ~20.32% | L4: Listed (IDX: AALI) | M4: Palm oil plantation (upstream) + CPO/PKO refining + NPK blending | Q4: Ageing plantation profile (avg age 16.7 yrs, ~71% of mature area >15 yrs); structural decline risk in productivity; dependence on replanting & 3rd-party FFB. | R4: Strong 2025: revenue +31% to Rp28.7 tn, net profit +28% to Rp1.47 tn on +11% CPO ASP and +13% sales volume. Company repaid all bank loans; gearing <1%, current ratio 4.3x, cash Rp2.76 tn. 64% domestic / 36% export. FFB total 3.82 mt (+2%), third-party FFB 2.41 mt (+11%), CPO 1.20 mt. | S4: Integrated
A5: PT Andira Agro Tbk | B5: ANDI | C5: IDX | D5: 2022 | E5: ANDI_2022_AR.pdf | F5: Jakarta, Indonesia (HO); Banyuasin, South Sumatra (operations) | G5: Indonesia | H5: South Sumatra (Banyuasin) | I5: Private, small single-site palm company. Controlling shareholder PT Central Energi Pratama 49.73%. | J5: No disclosed subsidiaries; single-entity issuer focused on Banyuasin estates. | K5: PT Central Energi Pratama 49.73%, PT Anugerah Perkasa Semesta 7.49%, Kejaksaan Agung (Attorney General's Office) 6.07%, Public 36.71% | L5: Listed (IDX: ANDI) since 16 Aug 2018 | M5: Oil palm plantation + single palm oil mill (CPO and PK production) | Q5: Loss-making (net loss Rp10.8 bn in 2022, 3rd consecutive loss year); 14.9x normalized CPO price declines hurt margins; share price stuck at Rp50 (listing floor); small scale (~4,453 ha HGU); high leverage (gross debt Rp166 bn vs equity Rp239 bn); Kejaksaan Agung 6.07% ownership unusual (post-suspected-case asset restitution). | R5: Small single-site palm producer in South Sumatra; 2022 revenue Rp317.9 bn (-8%), gross profit Rp22.8 bn (-40%), operating loss Rp10.5 bn (vs profit Rp9.8 bn in 2021), net loss Rp10.8 bn. FFB processed 121,298 t, CPO 21,524 t, PK 5,759 t. Mill capacity 30 tph. Share price Rp50 at IDX floor. Low trading liquidity. Assets Rp444 bn, equity Rp239 bn, gross bank debt Rp166 bn. | S5: Upstream
A6: PT Andira Agro Tbk | B6: ANDI | C6: IDX | D6: 2023 | E6: ANDI_2023_AR.pdf | F6: Jakarta, Indonesia (HO); Banyuasin, South Sumatra (operations) | G6: Indonesia | H6: South Sumatra (Banyuasin) | I6: Small single-site palm company. Controlling shareholder PT Central Energi Pratama 49.73%. | J6: No disclosed subsidiaries. | K6: PT Central Energi Pratama 49.73%, PT Anugerah Perkasa Semesta 7.49%, Kejaksaan Agung 6.07%, Public 36.71% (unchanged from 2022) | L6: Listed (IDX: ANDI) since 16 Aug 2018 | M6: Oil palm plantation + single palm oil mill (CPO and PK) | Q6: Deteriorating: revenue -31% to Rp219.9 bn, gross profit collapsed -99% to Rp0.22 bn, operating loss Rp63.1 bn (vs Rp10.5 bn 2022), net loss Rp56.0 bn (vs Rp10.8 bn). D/E 1.069x. Current ratio 0.58 - liquidity warning. Equity -23% to Rp182.7 bn. FFB volume -18% to 99,141 t; CPO -20% to 17,178 t. | R6: Steep deterioration in 2023: revenue declined as CPO & PK volumes shrank and prices eased. Gross margin fell from 7.2% to 0.1%. Large operating loss. Current ratio below 1x. Equity shrinking from accumulated losses. Share price unchanged at Rp50 (listing floor). High risk, possible going concern concern if trend continues. | S6: Upstream
A7: PT Andira Agro Tbk | B7: ANDI | C7: IDX | D7: 2024 | E7: ANDI_2024_AR.pdf | F7: Jakarta, Indonesia (HO); Banyuasin, South Sumatra (operations) | G7: Indonesia | H7: South Sumatra (Banyuasin) | I7: Small single-site palm company. Controlling shareholder PT Central Energi Pratama 49.73%. | J7: No disclosed subsidiaries. | K7: PT Central Energi Pratama ~49.73%, PT Anugerah Perkasa Semesta ~7.49%, Kejaksaan Agung ~6.07%, Public ~36.71% (per 2023; 2024 page 64 disclosure) | L7: Listed (IDX: ANDI) since 16 Aug 2018 | M7: Oil palm plantation + single palm oil mill (CPO, PK, cangkang) | Q7: Severe share price collapse: Rp50 -> Rp6 (from Q2 2024); market cap shrank from Rp467.5 bn to Rp56.1 bn. 3rd straight year of losses. Revenue -11% to Rp196.7 bn. Gross profit negative (-Rp12.0 bn, GP margin -6.08%). Operating loss Rp34.6 bn. Net loss Rp23.1 bn. D/E rose to 1.19x. FFB volume -27% to 71,988 t. Current ratio 0.77. Receivables collection period ballooned from 77 to 323 days - major working capital stress. | R7: PT Andira Agro continued to deteriorate in 2024; FFB volume down to 72k t, CPO down to 11,546 t. Share price collapsed from listing floor Rp50 to Rp6 in Q2-Q4. Working capital severely stressed (receivable days 323). Still loss-making with deeply negative gross margin. Going concern risk elevated. | S7: Upstream
A8: PT Austindo Nusantara Jaya Tbk | B8: ANJT | C8: IDX | D8: 2023 | E8: ANJT_2022_AR.pdf | F8: Jakarta, Indonesia | G8: Indonesia | H8: Sumatra/Kalimantan/Bangka Belitung/Southwest Papua | I8: Controlled by Tahija family via PT Memimpin Dengan Nurani (40.85%), PT Austindo Kencana Jaya (40.85%), George & Sjakon Tahija (4.74% each); Public 8.83% | J8: ANJA, ANJAS, SMM, KAL, GSB, PPM, PMP, ANJAP, LSP, AANE, GMIT, ANJB | K8: Tahija family ~91%; Public ~9%; Foundation (Yayasan Tahija) 0.0003% | L8: Listed (IDX: ANJT) since May 8, 2013 | M8: Palm oil plantation (upstream) + mills, sago, edamame, biogas renewable energy | Q8: FY2023 net profit collapsed to USD 1.9mn (-91% YoY) on lower CPO ASP and higher interest/depreciation | R8: Filename ANJT_2022_AR.txt actually corresponds to the 2023 Annual Report; primary year extracted is 2023. Reports in USD; converted to IDR bn at year-end rate ~15,394 IDR/USD. | S8: Integrated
A9: PT Austindo Nusantara Jaya Tbk | B9: ANJT | C9: IDX | D9: 2022 | E9: ANJT_2023_AR.pdf | F9: Jakarta, Indonesia | G9: Indonesia | H9: Sumatra/Kalimantan/Bangka Belitung/Southwest Papua | I9: Controlled by Tahija family via PT Memimpin Dengan Nurani, PT Austindo Kencana Jaya, and individual Tahija holdings | J9: ANJA, ANJAS, SMM, KAL, GSB, PPM, PMP, ANJAP, LSP, AANE, GMIT, ANJB | K9: Tahija family ~91%; Public ~9% | L9: Listed (IDX: ANJT) since May 8, 2013 | M9: Palm oil plantation (upstream) + mills, sago, edamame, renewable energy | Q9: 2022 profit halved vs 2021 (USD 21.2mn vs 36.6mn) on lower CPO ASP; consistent plasma share stagnating | R9: Filename ANJT_2023_AR.txt corresponds to FY2022 Annual Report. Primary year = 2022. Reports in USD; converted at year-end 2022 ~15,568 IDR/USD. | S9: Integrated
A10: PT Austindo Nusantara Jaya Tbk | B10: ANJT | C10: IDX | D10: 2024 | E10: ANJT_2024_AR.pdf | F10: Jakarta, Indonesia | G10: Indonesia | H10: Sumatra/Kalimantan/Bangka Belitung/Southwest Papua | I10: Controlled by Tahija family via PT Memimpin Dengan Nurani, PT Austindo Kencana Jaya, and individual Tahija holdings | J10: ANJA, ANJAS, SMM, KAL, GSB, PPM, PMP, ANJAP, LSP, AANE, GMIT, ANJB | K10: Tahija family ~91%; Public ~9% | L10: Listed (IDX: ANJT) since May 8, 2013 | M10: Palm oil plantation (upstream) + 5 mills, sago concession, edamame, biogas renewable energy | Q10: FFB production -11.7% YoY due to El Nino aftermath; North Sumatra II plantation suffered flooding; CPO production -13.5% YoY | R10: 2024 was a recovery year with net income +107% YoY but FFB production down sharply from 2023 due to weather. Reports in USD; converted at ~16,162 IDR/USD year-end 2024. | S10: Integrated
A11: PT BISI International Tbk | B11: BISI | C11: IDX | D11: 2023 | E11: BISI_2023_AR.pdf | F11: Sidoarjo, East Java, Indonesia | G11: Indonesia | H11: Java (East Java HQ) - nationwide sales in Indonesia | I11: Part of Charoen Pokphand Group (Jiaravanon family controlling shareholder). Subsidiaries: PT Multi Sarana Indotani (99.91%), PT Tanindo Intertraco (99.96%) | J11: PT Multi Sarana Indotani (pesticide), PT Tanindo Intertraco (fertilizer/pesticide trading) | K11: PT Agrindo Pratama 31.00%; Field Investment Holdings 6.36%; Valley Investment Holdings 6.36%; Vista Investment Holdings 6.36%; SJ BISI Holdings 4.08%; Public 45.73% (Jiaravanon family control ~54%) | L11: Listed (IDX: BISI) | M11: Hybrid seed producer (corn, horticulture, rice) + pesticides + fertilizers - NOT palm oil | Q11: Palm-specific operational metrics are N/A (BISI is a seeds/agritech company, not palm plantation). Revenue fell 4.86% on adverse weather affecting corn seed production | R11: BISI is a hybrid seeds and agrochemicals company affiliated with PT Charoen Pokphand Indonesia (offtaker). No palm plantation/mill operations; palm-specific fields left empty. | S11: Other
A12: PT BISI International Tbk | B12: BISI | C12: IDX | D12: 2024 | E12: BISI_2024_AR.pdf | F12: Sidoarjo, East Java, Indonesia | G12: Indonesia | H12: Java (East Java HQ) - nationwide sales in Indonesia | I12: Part of Charoen Pokphand Group (Jiaravanon family controlling shareholder). Subsidiaries: PT Multi Sarana Indotani, PT Tanindo Intertraco | J12: PT Multi Sarana Indotani (pesticide), PT Tanindo Intertraco (fertilizer/pesticide trading) | K12: PT Agrindo Pratama 31.00%; Field/Valley/Vista Investment Holdings 6.36% each; SJ BISI Holdings 4.08%; Public ~45.7% (Jiaravanon family control) | L12: Listed (IDX: BISI) | M12: Hybrid seed producer (corn, horticulture, rice) + pesticides + fertilizers | Q12: Revenue collapsed 40%; net profit -70% YoY due to weather-driven reduction in corn seed sales; operating CF was negative Rp 146 bn in 2024 | R12: BISI is a seeds/agritech company, not palm oil; palm-specific operational fields are N/A. 2024 was a weak year due to adverse weather and delayed planting seasons. | S12: Other
A13: PT BISI International Tbk | B13: BISI | C13: IDX | D13: 2025 | E13: BISI_2025_AR.pdf | F13: Sidoarjo, East Java, Indonesia | G13: Indonesia | H13: Java (East Java HQ) - nationwide sales in Indonesia | I13: Part of Charoen Pokphand Group (Jiaravanon family controlling shareholder) | J13: Subsidiaries from prior AR: PT Multi Sarana Indotani, PT Tanindo Intertraco | K13: Controlled by Jiaravanon family via PT Agrindo Pratama (31%) and BVI holding companies | L13: Listed (IDX: BISI) | M13: Hybrid seed producer (corn, horticulture, rice) + pesticides + fertilizers | Q13: Source file is consolidated financial statements only (audited FS, not full Annual Report). Operating CF still negative at Rp -263 bn in 2025; cash position fell sharply from Rp 568 bn to Rp 167 bn | R13: BISI_2025 source is only the consolidated audited financial statements (not a full AR). Operational/ESG sections not available. Revenue recovered 24% YoY to Rp 1,696 bn. | S13: Other
A14: PT Bumi Teknokultura Unggul Tbk | B14: BTEK | C14: IDX | D14: 2022 | E14: BTEK_2022_AR.pdf | F14: Jakarta Timur, Indonesia | G14: Indonesia | H14: Java (Tangerang) - cocoa processing | I14: Holding company with subsidiary PT Golden Harvest Cocoa Indonesia (cocoa bean processing); also owns Golden Harvest Cocoa Pte. Ltd. (Singapore). | J14: PT Golden Harvest Cocoa Indonesia; Golden Harvest Cocoa Pte. Ltd. | K14: Golden Harvest Cocoa Ltd 41.59%; Kejaksaan Agung 5.25%; public <5%. | L14: Listed (IDX: BTEK) | M14: Cocoa bean processing (cocoa butter, cocoa cake, cocoa powder). Not a palm-oil producer. | Q14: Not a palm oil company despite inclusion in palm longlist; cocoa processing. Current ratio 0.35, DER 2.44x, bank loans Rp 2,478 bn vs total equity Rp 1,203 bn; gross loss and net comprehensive loss Rp 358.68 bn (2022). | R14: BTEK is a cocoa (kakao) bean processor, not a palm oil producer. Financial statement in raw rupiah (header 'dalam Ribuan Rupiah' appears mislabeled; narrative figures confirm raw rupiah). Heavy leverage, continued losses. | S14: Other
... A94: PT Wahana Pronatural Tbk | B94: WAPO | C94: IDX | D94: 2024 | E94: WAPO_2024_AR.pdf | F94: Surabaya, Indonesia | G94: Indonesia | H94: Java/Surabaya (HQ); candy factory in Bogor West Java (leased out); coffee-bean trading operations national | I94: Small trading-industrial company. No disclosed subsidiaries; standalone (non-consolidated) financials. Controlling shareholders PT Hijau Sari (36.07%) and PT Mitra Niaga Sakti (32.44%). | J94: None disclosed in the AR (standalone financial statements). | K94: PT Hijau Sari 36.07%, PT Mitra Niaga Sakti 32.44%, PT Surya Pelangi Mandiri 8.06%, PT Pesona Bangun Mandiri 4.43%, Public <5% 19.00%. Total 1,240,923,111 shares. | L94: Listed (IDX: WAPO); IPO 22 June 2001. | M94: Trading company - coffee beans (green beans) as 97% of 2024 revenue, with minor contributions from AirAlam bottled water (1.1%), Sunkist Water C vitamin drink (1%), and dried seaweed (0.4%). NOT a palm oil producer. | Q94: NOT A PALM OIL COMPANY. WAPO is a coffee-bean (green bean) trading house with minor beverage/seaweed activity. No oil-palm plantations, CPO mills, FFB production or any palm processing. Revenue surged 404% YoY in 2024 driven by coffee-bean trade volumes (30,000 t), but margins remain razor-thin (gross margin 1.2%, operating margin 0.02%). Only 9 employees. Ticker should likely be EXCLUDED from the Indonesian palm long-list - clearly does not belong in palm oil peer set. | R94: PT Wahana Pronatural Tbk posted 2024 net sales of Rp 2,122.33 bn (+404% YoY), almost entirely driven by green-bean coffee trading (30,000 t at inflated global prices; 97% of revenue). Gross profit Rp 24.65 bn, operating profit Rp 0.52 bn (vs Rp -0.36 bn loss in 2023), and net profit Rp 0.72 bn (comprehensive Rp 0.78 bn). Total assets fell to Rp 86.59 bn from Rp 131.94 bn as trade receivables collapsed from Rp 61.1 bn to Rp 4.7 bn. No palm-oil operations anywhere. Company has a negligible employee count (9) and trades commodities rather than producing them. | S94: Other

Sheet Asset_Operations
A1: Company | B1: Planted Area Total (ha) | C1: Nucleus Area (ha) | D1: Plasma Area (ha) | E1: Mature Area (ha) | F1: Immature Area (ha) | G1: Productive Age Area (ha) | H1: Old Age Area (ha) | I1: Average Tree Age (years) | J1: Replanting Area (ha) | K1: Sumatra Area (ha) | L1: Kalimantan Area (ha) | M1: Sulawesi Area (ha) | N1: Other Region Area (ha) | O1: Mills Count (#) | P1: Mill Capacity (tph) | Q1: Kernel Crushing Count (#) | R1: Kernel Crushing Capacity (tph) | S1: CPO Refinery Count (#) | T1: CPO Refinery Capacity (tpa) | U1: PKO Refinery Count (#) | V1: PKO Refinery Capacity (tpa) | W1: NPK Plant Count (#) | X1: Jetty/Logistics Note | Y1: Power Infrastructure Note | Z1: Road Infrastructure Note | AA1: Third-Party FFB (t) | AB1: Third-Party Dependence (%) [auto] | AC1: FFB Production (t) | AD1: Nucleus FFB (t) | AE1: Plasma FFB (t) | AF1: FFB Processed (t) | AG1: CPO Production (t) | AH1: Kernel Production (t) | AI1: PKO Production (t) | AJ1: RBDPO Production (t) | AK1: Olein Production (t) | AL1: Stearin Production (t) | AM1: PFAD Production (t) | AN1: PKE Production (t) | AO1: FFB Yield (t/ha) [auto = FFB Prod/Mature Area] | AP1: Nucleus FFB Yield (t/ha) [auto] | AQ1: CPO Yield (t/ha) [auto = CPO Prod/Mature Area] | AR1: OER (%) [auto = CPO/FFB Processed] | AS1: KER (%) [auto = Kernel/FFB Processed] | AT1: PKO Extraction (%) [auto] | AU1: PKE Extraction (%) [auto] | AV1: Average CPO Selling Price (local ccy/kg) | AW1: Domestic Sales (%) | AX1: Export Sales (%) | AY1: Asset Quality Note | AZ1: Ops Risk Note | BA1: Digitalization Note | BB1: Sustainability Ops Note | BC1: OER vs Own FFB (%) [auto = CPO/Own FFB] | BD1: OER vs Total Available FFB (%) [auto = CPO/(Own+3rd Party)] | BE1: OER Reported (%) (manual; company disclosure) | BF1: OER Method Note (manual) | BG1: Report Year
A2: PT Astra Agro Lestari Tbk | B2: 285387 | C2: 213158 | D2: 72229 | E2: 265518 | F2: 19869 | G2: 102319 | H2: 163199 | I2: 16.2 | K2: 105300 | L2: 129804 | M2: 50283 | N2: 0 | O2: 32 | P2: 1570 | Q2: 14 | S2: 2 | U2: 1 | W2: 2 | AA2: 2398457 | AB2: =IFERROR(AA2/AF2,"") | AC2: 3312149 | AD2: 3312149 | AE2: 1041496 | AF2: 6752102 | AG2: 1275539 | AH2: 272310 | AI2: 45158 | AJ2: 17289 | AK2: 441671 | AL2: 115918 | AM2: 23621 | AN2: 56142 | AO2: =IFERROR(AC2/E2,"") | AP2: =IFERROR(AD2/E2,"") | AQ2: =IFERROR(AG2/E2,"") | AR2: =IFERROR(AG2/AF2,"") | AS2: =IFERROR(AH2/AF2,"") | AT2: =IFERROR(AI2/AH2,"") | AU2: =IFERROR(AN2/AH2,"") | AV2: 12948 | BC2: =IFERROR(AG2/AC2,"") | BD2: =IFERROR(AG2/(AC2+AA2),"") | BE2: 0.1889 | BF2: Reported CPO Extraction Rate 18.89% (p.13 "Rendemen Minyak Sawit") | BG2: 2023
A3: PT Astra Agro Lestari Tbk | B3: 284831 | C3: 212602 | D3: 72229 | E3: 265490 | F3: 19341 | G3: 87761 | H3: 177729 | I3: 16.5 | K3: 104376 | L3: 130043 | M3: 50412 | O3: 32 | P3: 1570 | Q3: 14 | S3: 2 | U3: 1 | W3: 2 | AA3: 2180762 | AB3: =IFERROR(AA3/AF3,"") | AC3: 3002685 | AD3: 3002685 | AE3: 731773 | AF3: 5915220 | AG3: 1125388 | AH3: 234121 | AI3: 46454 | AJ3: 14760 | AK3: 388106 | AL3: 95826 | AM3: 19382 | AN3: 57001 | AO3: =IFERROR(AC3/E3,"") | AP3: =IFERROR(AD3/E3,"") | AQ3: =IFERROR(AG3/E3,"") | AR3: =IFERROR(AG3/AF3,"") | AS3: =IFERROR(AH3/AF3,"") | AT3: =IFERROR(AI3/AH3,"") | AU3: =IFERROR(AN3/AH3,"") | AV3: 12883 | AW3: 0.69 | AX3: 0.31 | BC3: =IFERROR(AG3/AC3,"") | BD3: =IFERROR(AG3/(AC3+AA3),"") | BE3: 0.1903 | BF3: Reported CPO Extraction Rate 19.03% (p.15 'Rendemen Minyak Sawit') | BG3: 2024
A4: PT Astra Agro Lestari Tbk | B4: 280325 | C4: 208063 | D4: 72262 | E4: 260927 | F4: 19399 | G4: 76292 | H4: 184635 | I4: 16.7 | K4: 103389 | L4: 129093 | M4: 47843 | O4: 32 | P4: 1655 | Q4: 14 | S4: 2 | U4: 1 | W4: 2 | AA4: 2409810 | AB4: =IFERROR(AA4/AF4,"") | AC4: 3009024 | AD4: 3009024 | AE4: 812535 | AF4: 6231369 | AG4: 1197514 | AH4: 251874 | AI4: 60451 | AJ4: 17718 | AK4: 457987 | AL4: 119496 | AM4: 26920 | AN4: 74765 | AO4: =IFERROR(AC4/E4,"") | AP4: =IFERROR(AD4/E4,"") | AQ4: =IFERROR(AG4/E4,"") | AR4: =IFERROR(AG4/AF4,"") | AS4: =IFERROR(AH4/AF4,"") | AT4: =IFERROR(AI4/AH4,"") | AU4: =IFERROR(AN4/AH4,"") | AV4: 14316 | AW4: 0.64 | AX4: 0.36 | BC4: =IFERROR(AG4/AC4,"") | BD4: =IFERROR(AG4/(AC4+AA4),"") | BE4: 0.1922 | BF4: Reported CPO Extraction Rate 19.22% (p.16 'Rendemen Minyak Sawit') | BG4: 2025
A5: PT Andira Agro Tbk | E5: 5040.63 | K5: 4453 | O5: 1 | P5: 30 | AB5: =IFERROR(AA5/AF5,"") | AF5: 121298 | AG5: 21524 | AH5: 5759 | AO5: =IFERROR(AC5/E5,"") | AP5: =IFERROR(AD5/E5,"") | AQ5: =IFERROR(AG5/E5,"") | AR5: =IFERROR(AG5/AF5,"") | AS5: =IFERROR(AH5/AF5,"") | AT5: =IFERROR(AI5/AH5,"") | AU5: =IFERROR(AN5/AH5,"") | BC5: =IFERROR(AG5/AC5,"") | BD5: =IFERROR(AG5/(AC5+AA5),"") | BE5: 0.1775 | BF5: Calculated OER = CPO 21,524 / FFB processed 121,298 = 17.75% | BG5: 2022
A6: PT Andira Agro Tbk | B6: 10006.31 | C6: 5040.63 | D6: 4965.68 | E6: 5040.63 | K6: 4453 | O6: 1 | P6: 30 | Q6: 0 | S6: 0 | AB6: =IFERROR(AA6/AF6,"") | AF6: 99141 | AG6: 17178 | AH6: 4620 | AO6: =IFERROR(AC6/E6,"") | AP6: =IFERROR(AD6/E6,"") | AQ6: =IFERROR(AG6/E6,"") | AR6: =IFERROR(AG6/AF6,"") | AS6: =IFERROR(AH6/AF6,"") | AT6: =IFERROR(AI6/AH6,"") | AU6: =IFERROR(AN6/AH6,"") | BC6: =IFERROR(AG6/AC6,"") | BD6: =IFERROR(AG6/(AC6+AA6),"") | BE6: 0.1733 | BF6: Calculated OER = CPO 17,178 / FFB 99,141 = 17.33% | BG6: 2023
A7: PT Andira Agro Tbk | B7: 9709.24 | C7: 4743.56 | D7: 4965.68 | E7: 4558.21 | F7: 185.35 | K7: 4453 | O7: 1 | P7: 30 | Q7: 0 | S7: 0 | AB7: =IFERROR(AA7/AF7,"") | AF7: 71988 | AG7: 11546 | AH7: 3166 | AO7: =IFERROR(AC7/E7,"") | AP7: =IFERROR(AD7/E7,"") | AQ7: =IFERROR(AG7/E7,"") | AR7: =IFERROR(AG7/AF7,"") | AS7: =IFERROR(AH7/AF7,"") | AT7: =IFERROR(AI7/AH7,"") | AU7: =IFERROR(AN7/AH7,"") | AW7: 1 | AX7: 0 | BC7: =IFERROR(AG7/AC7,"") | BD7: =IFERROR(AG7/(AC7+AA7),"") | BE7: 0.1604 | BF7: Calculated OER = CPO 11,546 / FFB 71,988 = 16.04% | BG7: 2024
A8: PT Austindo Nusantara Jaya Tbk | B8: 48516 | C8: 43400 | D8: 5116 | E8: 43400 | F8: 5174 | I8: 13 | K8: 26049 | L8: 9051 | N8: 13416 | O8: 5 | P8: 315 | Q8: 1 | S8: 0 | AA8: 503811 | AB8: =IFERROR(AA8/AF8,"") | AC8: 881051 | AF8: 1374871 | AG8: 283659 | AH8: 57477 | AI8: 1459 | AO8: =IFERROR(AC8/E8,"") | AP8: =IFERROR(AD8/E8,"") | AQ8: =IFERROR(AG8/E8,"") | AR8: =IFERROR(AG8/AF8,"") | AS8: =IFERROR(AH8/AF8,"") | AT8: =IFERROR(AI8/AH8,"") | AU8: =IFERROR(AN8/AH8,"") | AV8: 11253 | AW8: 0.9976 | AX8: 0.0024 | BC8: =IFERROR(AG8/AC8,"") | BD8: =IFERROR(AG8/(AC8+AA8),"") | BE8: 0.206 | BF8: CPO Extraction Rate 20.6% (p.11, Palm Oil Production table). USD 731/t ASP converted to Rp/kg at 15,394 IDR/USD. | BG8: 2023
A9: PT Austindo Nusantara Jaya Tbk | B9: 49409 | C9: 43700 | D9: 5709 | E9: 42200 | F9: 7338 | I9: 12.9 | K9: 26491 | L9: 9051 | N9: 13867 | O9: 5 | P9: 315 | Q9: 1 | S9: 0 | AA9: 538483 | AB9: =IFERROR(AA9/AF9,"") | AC9: 840581 | AF9: 1379064 | AG9: 275769 | AH9: 55011 | AI9: 1052 | AO9: =IFERROR(AC9/E9,"") | AP9: =IFERROR(AD9/E9,"") | AQ9: =IFERROR(AG9/E9,"") | AR9: =IFERROR(AG9/AF9,"") | AS9: =IFERROR(AH9/AF9,"") | AT9: =IFERROR(AI9/AH9,"") | AU9: =IFERROR(AN9/AH9,"") | AV9: 13109 | AW9: 0.9967 | AX9: 0.0033 | BC9: =IFERROR(AG9/AC9,"") | BD9: =IFERROR(AG9/(AC9+AA9),"") | BE9: 0.201 | BF9: CPO Extraction Rate 20.1% (p.8). USD 842/t ASP x ~15,568 IDR/USD. | BG9: 2022
A10: PT Austindo Nusantara Jaya Tbk | B10: 53357 | C10: 48352 | D10: 5005 | E10: 42176 | F10: 6212 | I10: 12.9 | J10: 1718 | K10: 26049 | L10: 9163 | N10: 18145 | O10: 5 | P10: 315 | Q10: 1 | S10: 0 | AA10: 463835 | AB10: =IFERROR(AA10/AF10,"") | AC10: 777615 | AF10: 1233180 | AG10: 245395 | AH10: 51889 | AI10: 1121 | AO10: =IFERROR(AC10/E10,"") | AP10: =IFERROR(AD10/E10,"") | AQ10: =IFERROR(AG10/E10,"") | AR10: =IFERROR(AG10/AF10,"") | AS10: =IFERROR(AH10/AF10,"") | AT10: =IFERROR(AI10/AH10,"") | AU10: =IFERROR(AN10/AH10,"") | AV10: 13285 | BC10: =IFERROR(AG10/AC10,"") | BD10: =IFERROR(AG10/(AC10+AA10),"") | BE10: 0.199 | BF10: Combined OER 19.9% (CPO production / total FFB processed). USD 822/t x 16,162 IDR/USD. | BG10: 2024
A11: PT BISI International Tbk | AB11: =IFERROR(AA11/AF11,"") | AO11: =IFERROR(AC11/E11,"") | AP11: =IFERROR(AD11/E11,"") | AQ11: =IFERROR(AG11/E11,"") | AR11: =IFERROR(AG11/AF11,"") | AS11: =IFERROR(AH11/AF11,"") | AT11: =IFERROR(AI11/AH11,"") | AU11: =IFERROR(AN11/AH11,"") | BC11: =IFERROR(AG11/AC11,"") | BD11: =IFERROR(AG11/(AC11+AA11),"") | BG11: 2023
A12: PT BISI International Tbk | AB12: =IFERROR(AA12/AF12,"") | AO12: =IFERROR(AC12/E12,"") | AP12: =IFERROR(AD12/E12,"") | AQ12: =IFERROR(AG12/E12,"") | AR12: =IFERROR(AG12/AF12,"") | AS12: =IFERROR(AH12/AF12,"") | AT12: =IFERROR(AI12/AH12,"") | AU12: =IFERROR(AN12/AH12,"") | BC12: =IFERROR(AG12/AC12,"") | BD12: =IFERROR(AG12/(AC12+AA12),"") | BG12: 2024
A13: PT BISI International Tbk | AB13: =IFERROR(AA13/AF13,"") | AO13: =IFERROR(AC13/E13,"") | AP13: =IFERROR(AD13/E13,"") | AQ13: =IFERROR(AG13/E13,"") | AR13: =IFERROR(AG13/AF13,"") | AS13: =IFERROR(AH13/AF13,"") | AT13: =IFERROR(AI13/AH13,"") | AU13: =IFERROR(AN13/AH13,"") | BC13: =IFERROR(AG13/AC13,"") | BD13: =IFERROR(AG13/(AC13+AA13),"") | BG13: 2025
A14: PT Bumi Teknokultura Unggul Tbk | AB14: =IFERROR(AA14/AF14,"") | AO14: =IFERROR(AC14/E14,"") | AP14: =IFERROR(AD14/E14,"") | AQ14: =IFERROR(AG14/E14,"") | AR14: =IFERROR(AG14/AF14,"") | AS14: =IFERROR(AH14/AF14,"") | AT14: =IFERROR(AI14/AH14,"") | AU14: =IFERROR(AN14/AH14,"") | BC14: =IFERROR(AG14/AC14,"") | BD14: =IFERROR(AG14/(AC14+AA14),"") | BG14: 2022
A15: PT Bumi Teknokultura Unggul Tbk | AB15: =IFERROR(AA15/AF15,"") | AO15: =IFERROR(AC15/E15,"") | AP15: =IFERROR(AD15/E15,"") | AQ15: =IFERROR(AG15/E15,"") | AR15: =IFERROR(AG15/AF15,"") | AS15: =IFERROR(AH15/AF15,"") | AT15: =IFERROR(AI15/AH15,"") | AU15: =IFERROR(AN15/AH15,"") | BC15: =IFERROR(AG15/AC15,"") | BD15: =IFERROR(AG15/(AC15+AA15),"") | BG15: 2023
A16: PT Bumi Teknokultura Unggul Tbk | AB16: =IFERROR(AA16/AF16,"") | AO16: =IFERROR(AC16/E16,"") | AP16: =IFERROR(AD16/E16,"") | AQ16: =IFERROR(AG16/E16,"") | AR16: =IFERROR(AG16/AF16,"") | AS16: =IFERROR(AH16/AF16,"") | AT16: =IFERROR(AI16/AH16,"") | AU16: =IFERROR(AN16/AH16,"") | BC16: =IFERROR(AG16/AC16,"") | BD16: =IFERROR(AG16/(AC16+AA16),"") | BG16: 2024
A17: PT Eagle High Plantations Tbk | B17: 87000 | E17: 87000 | F17: 0 | K17: 2000 | L17: 73000 | N17: 12000 | O17: 7 | P17: 370 | Q17: 0 | S17: 0 | AA17: 272931 | AB17: =IFERROR(AA17/AF17,"") | AC17: 975251 | AD17: 930761 | AE17: 154180 | AF17: 1357872 | AG17: 320107 | AH17: 59278 | AO17: =IFERROR(AC17/E17,"") | AP17: =IFERROR(AD17/E17,"") | AQ17: =IFERROR(AG17/E17,"") | AR17: =IFERROR(AG17/AF17,"") | AS17: =IFERROR(AH17/AF17,"") | AT17: =IFERROR(AI17/AH17,"") | AU17: =IFERROR(AN17/AH17,"") | AV17: 11015 | AW17: 1 | AX17: 0 | BC17: =IFERROR(AG17/AC17,"") | BD17: =IFERROR(AG17/(AC17+AA17),"") | BE17: 0.2357 | BF17: Derived as CPO production (320,107 t) / FFB processed (1,357,872 t); AR does not report OER directly. | BG17: 2023
A18: PT Eagle High Plantations Tbk | B18: 87000 | E18: 86729 | F18: 271 | K18: 2000 | L18: 73000 | N18: 12000 | O18: 7 | P18: 370 | Q18: 0 | S18: 0 | AB18: =IFERROR(AA18/AF18,"") | AC18: 1041515 | AG18: 263657 | AH18: 49193 | AO18: =IFERROR(AC18/E18,"") | AP18: =IFERROR(AD18/E18,"") | AQ18: =IFERROR(AG18/E18,"") | AR18: =IFERROR(AG18/AF18,"") | AS18: =IFERROR(AH18/AF18,"") | AT18: =IFERROR(AI18/AH18,"") | AU18: =IFERROR(AN18/AH18,"") | AV18: 12515 | BC18: =IFERROR(AG18/AC18,"") | BD18: =IFERROR(AG18/(AC18+AA18),"") | BE18: 0.236 | BG18: 2024
A19: PT Eagle High Plantations Tbk | B19: 74339 | E19: 74068 | F19: 271 | O19: 7 | P19: 370 | AB19: =IFERROR(AA19/AF19,"") | AO19: =IFERROR(AC19/E19,"") | AP19: =IFERROR(AD19/E19,"") | AQ19: =IFERROR(AG19/E19,"") | AR19: =IFERROR(AG19/AF19,"") | AS19: =IFERROR(AH19/AF19,"") | AT19: =IFERROR(AI19/AH19,"") | AU19: =IFERROR(AN19/AH19,"") | BC19: =IFERROR(AG19/AC19,"") | BD19: =IFERROR(AG19/(AC19+AA19),"") | BG19: 2025
A20: PT Citra Borneo Utama Tbk | O20: 0 | Q20: 1 | R20: 25 | S20: 1 | T20: 850000 | U20: 0 | AB20: =IFERROR(AA20/AF20,"") | AO20: =IFERROR(AC20/E20,"") | AP20: =IFERROR(AD20/E20,"") | AQ20: =IFERROR(AG20/E20,"") | AR20: =IFERROR(AG20/AF20,"") | AS20: =IFERROR(AH20/AF20,"") | AT20: =IFERROR(AI20/AH20,"") | AU20: =IFERROR(AN20/AH20,"") | AW20: 0.2254 | AX20: 0.7746 | AZ20: 780,010 MT total production (8.23% below 850,000 MT target); Refinery utilization 91.77% (up from 63.44%); Fractionation utilization 84.95%; Kernel crushing utilization 35.81%. CPO refinery yields: RBDPO 95.76%, PFAD 3.76%. Fractionation yields: Olein 81.01%, Stearin 18.99%. | BC20: =IFERROR(AG20/AC20,"") | BD20: =IFERROR(AG20/(AC20+AA20),"") | BG20: 2023
A21: PT Citra Borneo Utama Tbk | O21: 0 | Q21: 1 | R21: 25 | S21: 1 | T21: 850000 | U21: 0 | AB21: =IFERROR(AA21/AF21,"") | AJ21: 387833 | AK21: 296406 | AL21: 67661 | AM21: 14659 | AO21: =IFERROR(AC21/E21,"") | AP21: =IFERROR(AD21/E21,"") | AQ21: =IFERROR(AG21/E21,"") | AR21: =IFERROR(AG21/AF21,"") | AS21: =IFERROR(AH21/AF21,"") | AT21: =IFERROR(AI21/AH21,"") | AU21: =IFERROR(AN21/AH21,"") | AW21: 0.2366 | AX21: 0.7634 | AZ21: Total production 402,492 MT (47.59% of 845,750 MT target). Refinery CPO processing utilization 47.62% (down from 91.77%), non-processing 29.39%, total 77.01%. Fractionation utilization 42.83% (vs 84.95%). Kernel crushing utilization 29.00%. Yields: RBDPO 95.82%, PFAD 3.62%; Olein 81.42%, Stearin 18.58%; CPKO 40.42%, PKE 54.97%. Kernel storage expanded to 12,500t. | BC21: =IFERROR(AG21/AC21,"") | BD21: =IFERROR(AG21/(AC21+AA21),"") | BG21: 2024
A22: PT Citra Borneo Utama Tbk | O22: 0 | Q22: 1 | R22: 25 | S22: 1 | T22: 850000 | U22: 0 | AB22: =IFERROR(AA22/AF22,"") | AJ22: 578928 | AK22: 467921 | AL22: 101320 | AM22: 21898 | AO22: =IFERROR(AC22/E22,"") | AP22: =IFERROR(AD22/E22,"") | AQ22: =IFERROR(AG22/E22,"") | AR22: =IFERROR(AG22/AF22,"") | AS22: =IFERROR(AH22/AF22,"") | AT22: =IFERROR(AI22/AH22,"") | AU22: =IFERROR(AN22/AH22,"") | AW22: 0.2136 | AX22: 0.7864 | AZ22: Total production 603,670 MT (71.02% of 850,000 MT target). Refinery utilization 71.02%; Fractionation utilization 66.97%; Kernel crushing 50.66%. Yields: RBDPO 95.90%, PFAD 3.63%; Olein 82.21%, Stearin 17.78%; CPKO 42.09%, PKE 54.44%. New bottling capacity 222,222 L/day (68.23% Minyak Kita, 31.77% Hanau) utilization 41.95%. | BC22: =IFERROR(AG22/AC22,"") | BD22: =IFERROR(AG22/(AC22+AA22),"") | BG22: 2025
A23: PT Cisadane Sawit Raya Tbk. | B23: 19333.9 | C23: 19333.9 | E23: 16147.1 | F23: 3186.8 | G23: 12053.3 | H23: 4093.8 | K23: 19333.9 | O23: 1 | P23: 45 | Q23: 0 | S23: 0 | AA23: 14326 | AB23: =IFERROR(AA23/AF23,"") | AC23: 342464 | AD23: 342464 | AF23: 174180 | AG23: 35701 | AH23: 8974 | AO23: =IFERROR(AC23/E23,"") | AP23: =IFERROR(AD23/E23,"") | AQ23: =IFERROR(AG23/E23,"") | AR23: =IFERROR(AG23/AF23,"") | AS23: =IFERROR(AH23/AF23,"") | AT23: =IFERROR(AI23/AH23,"") | AU23: =IFERROR(AN23/AH23,"") | AV23: 12468 | AW23: 1 | AX23: 0 | BC23: =IFERROR(AG23/AC23,"") | BD23: =IFERROR(AG23/(AC23+AA23),"") | BE23: 0.205 | BF23: OER 20.5% and KER 5.2% (Extraction rates of CPO and Kernel from FFB processed) | BG23: 2022
A24: PT Cisadane Sawit Raya Tbk. | B24: 19552 | C24: 19552 | D24: 183.71 | E24: 17258.3 | F24: 2293.7 | G24: 13227.2 | H24: 4031.1 | K24: 19552 | O24: 2 | P24: 90 | Q24: 0 | S24: 0 | AA24: 26402 | AB24: =IFERROR(AA24/AF24,"") | AC24: 337367 | AD24: 337367 | AF24: 229687 | AG24: 48663 | AH24: 11166 | AO24: =IFERROR(AC24/E24,"") | AP24: =IFERROR(AD24/E24,"") | AQ24: =IFERROR(AG24/E24,"") | AR24: =IFERROR(AG24/AF24,"") | AS24: =IFERROR(AH24/AF24,"") | AT24: =IFERROR(AI24/AH24,"") | AU24: =IFERROR(AN24/AH24,"") | AV24: 10821 | AW24: 1 | AX24: 0 | BC24: =IFERROR(AG24/AC24,"") | BD24: =IFERROR(AG24/(AC24+AA24),"") | BE24: 0.212 | BF24: OER 21.2% and KER 4.9%. Two palm oil mills operational in 2023 (existing Sei Siarti 45 tph + PT SKL South Tapanuli 45 tph). Total capacity now 90 tph. | BG24: 2023
A25: PT Cisadane Sawit Raya Tbk. | B25: 20067.6 | C25: 20067.6 | D25: 868.8 | E25: 17430.9 | F25: 2636.7 | G25: 13352 | H25: 4078.9 | K25: 20067.6 | O25: 2 | P25: 90 | Q25: 0 | S25: 0 | AA25: 33723 | AB25: =IFERROR(AA25/AF25,"") | AC25: 319085 | AD25: 319085 | AF25: 265837 | AG25: 55700 | AH25: 11801 | AO25: =IFERROR(AC25/E25,"") | AP25: =IFERROR(AD25/E25,"") | AQ25: =IFERROR(AG25/E25,"") | AR25: =IFERROR(AG25/AF25,"") | AS25: =IFERROR(AH25/AF25,"") | AT25: =IFERROR(AI25/AH25,"") | AU25: =IFERROR(AN25/AH25,"") | AV25: 12793 | AW25: 1 | AX25: 0 | BC25: =IFERROR(AG25/AC25,"") | BD25: =IFERROR(AG25/(AC25+AA25),"") | BE25: 0.21 | BF25: OER 21.0% and KER 4.4%. Two operational mills (Sei Siarti 45 tph + PT SKL 45 tph, total 90 tph). Third mill at PT BKL Banyuasin (South Sumatra) in construction (~45 tph), target Jun-2025. | BG25: 2024
A26: PT Dharma Satya Nusantara Tbk | B26: 112500 | C26: 84600 | D26: 28300 | E26: 104000 | F26: 8800 | I26: 12.8 | L26: 112500 | O26: 12 | P26: 675 | Q26: 1 | R26: 16.7 | S26: 0 | AB26: =IFERROR(AA26/AF26,"") | AC26: 2213698 | AD26: 1758257 | AE26: 455442 | AF26: 2809177 | AG26: 639480 | AH26: 117622 | AI26: 37970 | AO26: =IFERROR(AC26/E26,"") | AP26: =IFERROR(AD26/E26,"") | AQ26: =IFERROR(AG26/E26,"") | AR26: =IFERROR(AG26/AF26,"") | AS26: =IFERROR(AH26/AF26,"") | AT26: =IFERROR(AI26/AH26,"") | AU26: =IFERROR(AN26/AH26,"") | AV26: 11180 | AW26: 1 | AX26: 0 | BC26: =IFERROR(AG26/AC26,"") | BD26: =IFERROR(AG26/(AC26+AA26),"") | BE26: 0.2276 | BF26: CPO OER as reported in MD&A for palm oil segment; FFA 3.78% | BG26: 2022
A27: PT Dharma Satya Nusantara Tbk | B27: 112700 | C27: 84800 | D27: 27900 | E27: 105700 | F27: 7000 | I27: 13.3 | L27: 112700 | O27: 12 | P27: 675 | Q27: 1 | R27: 16.7 | S27: 0 | AA27: 582738 | AB27: =IFERROR(AA27/AF27,"") | AC27: 2271821 | AD27: 1796532 | AE27: 475289 | AF27: 2854559 | AG27: 661892 | AH27: 122732 | AI27: 40356 | AO27: =IFERROR(AC27/E27,"") | AP27: =IFERROR(AD27/E27,"") | AQ27: =IFERROR(AG27/E27,"") | AR27: =IFERROR(AG27/AF27,"") | AS27: =IFERROR(AH27/AF27,"") | AT27: =IFERROR(AI27/AH27,"") | AU27: =IFERROR(AN27/AH27,"") | AV27: 11390 | AW27: 1 | AX27: 0 | BC27: =IFERROR(AG27/AC27,"") | BD27: =IFERROR(AG27/(AC27+AA27),"") | BE27: 0.2319 | BF27: CPO OER as reported in MD&A; FFA 2.96% | BG27: 2023
A28: PT Dharma Satya Nusantara Tbk | B28: 110700 | C28: 82800 | D28: 27908 | E28: 104101 | F28: 6599 | I28: 14 | J28: 900 | L28: 110700 | O28: 12 | P28: 675 | Q28: 1 | R28: 16.7 | S28: 0 | AA28: 405349 | AB28: =IFERROR(AA28/AF28,"") | AC28: 2109737 | AD28: 1661979 | AE28: 447757 | AF28: 2515086 | AG28: 601508 | AH28: 114210 | AI28: 38217 | AO28: =IFERROR(AC28/E28,"") | AP28: =IFERROR(AD28/E28,"") | AQ28: =IFERROR(AG28/E28,"") | AR28: =IFERROR(AG28/AF28,"") | AS28: =IFERROR(AH28/AF28,"") | AT28: =IFERROR(AI28/AH28,"") | AU28: =IFERROR(AN28/AH28,"") | AV28: 12790 | AW28: 1 | AX28: 0 | BC28: =IFERROR(AG28/AC28,"") | BD28: =IFERROR(AG28/(AC28+AA28),"") | BE28: 0.2392 | BF28: CPO OER reported 23.92%; FFA 2.86% | BG28: 2024
A29: PT FAP Agri Tbk | B29: 88752 | C29: 77384 | D29: 11368 | E29: 82624 | F29: 6128 | I29: 11 | L29: 85420 | N29: 3332 | O29: 5 | Q29: 1 | S29: 0 | AB29: =IFERROR(AA29/AF29,"") | AC29: 1202008 | AF29: 1202008 | AG29: 277058 | AH29: 48192 | AI29: 11106 | AN29: 12433 | AO29: =IFERROR(AC29/E29,"") | AP29: =IFERROR(AD29/E29,"") | AQ29: =IFERROR(AG29/E29,"") | AR29: =IFERROR(AG29/AF29,"") | AS29: =IFERROR(AH29/AF29,"") | AT29: =IFERROR(AI29/AH29,"") | AU29: =IFERROR(AN29/AH29,"") | AV29: 13406 | AW29: 1 | AX29: 0 | BC29: =IFERROR(AG29/AC29,"") | BD29: =IFERROR(AG29/(AC29+AA29),"") | BF29: Approx CPO OER ~23% (277,058/1,202,008); not explicitly disclosed. ASP from revenue Rp3,888bn CPO / 290,111 tons ≈ Rp13,407/kg. | BG29: 2022
A30: PT FAP Agri Tbk | B30: 88752 | C30: 77434 | D30: 11318 | E30: 84128 | F30: 4623 | I30: 11.9 | L30: 85420 | N30: 3332 | O30: 6 | Q30: 1 | S30: 0 | AB30: =IFERROR(AA30/AF30,"") | AC30: 1261820 | AG30: 307674 | AH30: 55797 | AI30: 13370 | AN30: 15188 | AO30: =IFERROR(AC30/E30,"") | AP30: =IFERROR(AD30/E30,"") | AQ30: =IFERROR(AG30/E30,"") | AR30: =IFERROR(AG30/AF30,"") | AS30: =IFERROR(AH30/AF30,"") | AT30: =IFERROR(AI30/AH30,"") | AU30: =IFERROR(AN30/AH30,"") | AW30: 1 | AX30: 0 | BC30: =IFERROR(AG30/AC30,"") | BD30: =IFERROR(AG30/(AC30+AA30),"") | BF30: Approx CPO OER ~24.4% (307,674/1,261,820); not explicitly disclosed. | BG30: 2023
A31: PT FAP Agri Tbk | B31: 88701 | C31: 78315 | D31: 10386 | E31: 87633 | F31: 1068 | I31: 13 | L31: 85369 | N31: 3332 | O31: 6 | Q31: 1 | S31: 0 | AB31: =IFERROR(AA31/AF31,"") | AC31: 1312257 | AG31: 297758 | AH31: 52859 | AI31: 13692 | AN31: 15452 | AO31: =IFERROR(AC31/E31,"") | AP31: =IFERROR(AD31/E31,"") | AQ31: =IFERROR(AG31/E31,"") | AR31: =IFERROR(AG31/AF31,"") | AS31: =IFERROR(AH31/AF31,"") | AT31: =IFERROR(AI31/AH31,"") | AU31: =IFERROR(AN31/AH31,"") | AW31: 1 | AX31: 0 | BC31: =IFERROR(AG31/AC31,"") | BD31: =IFERROR(AG31/(AC31+AA31),"") | BF31: Approx CPO OER ~22.7% (297,758/1,312,257); not explicitly disclosed. FFB yield 14.97 t/ha. | BG31: 2024
A32: PT FKS Multi Agro Tbk | AB32: =IFERROR(AA32/AF32,"") | AO32: =IFERROR(AC32/E32,"") | AP32: =IFERROR(AD32/E32,"") | AQ32: =IFERROR(AG32/E32,"") | AR32: =IFERROR(AG32/AF32,"") | AS32: =IFERROR(AH32/AF32,"") | AT32: =IFERROR(AI32/AH32,"") | AU32: =IFERROR(AN32/AH32,"") | BC32: =IFERROR(AG32/AC32,"") | BD32: =IFERROR(AG32/(AC32+AA32),"") | BG32: 2022
A33: PT FKS Multi Agro Tbk | AB33: =IFERROR(AA33/AF33,"") | AO33: =IFERROR(AC33/E33,"") | AP33: =IFERROR(AD33/E33,"") | AQ33: =IFERROR(AG33/E33,"") | AR33: =IFERROR(AG33/AF33,"") | AS33: =IFERROR(AH33/AF33,"") | AT33: =IFERROR(AI33/AH33,"") | AU33: =IFERROR(AN33/AH33,"") | BC33: =IFERROR(AG33/AC33,"") | BD33: =IFERROR(AG33/(AC33+AA33),"") | BG33: 2023
A34: PT FKS Multi Agro Tbk | AB34: =IFERROR(AA34/AF34,"") | AO34: =IFERROR(AC34/E34,"") | AP34: =IFERROR(AD34/E34,"") | AQ34: =IFERROR(AG34/E34,"") | AR34: =IFERROR(AG34/AF34,"") | AS34: =IFERROR(AH34/AF34,"") | AT34: =IFERROR(AI34/AH34,"") | AU34: =IFERROR(AN34/AH34,"") | BC34: =IFERROR(AG34/AC34,"") | BD34: =IFERROR(AG34/(AC34+AA34),"") | BG34: 2024
A35: PT Golden Plantation Tbk | AB35: =IFERROR(AA35/AF35,"") | AO35: =IFERROR(AC35/E35,"") | AP35: =IFERROR(AD35/E35,"") | AQ35: =IFERROR(AG35/E35,"") | AR35: =IFERROR(AG35/AF35,"") | AS35: =IFERROR(AH35/AF35,"") | AT35: =IFERROR(AI35/AH35,"") | AU35: =IFERROR(AN35/AH35,"") | BC35: =IFERROR(AG35/AC35,"") | BD35: =IFERROR(AG35/(AC35+AA35),"") | BG35: 2020
A36: PT Gunanusa Eramandiri Tbk | AB36: =IFERROR(AA36/AF36,"") | AO36: =IFERROR(AC36/E36,"") | AP36: =IFERROR(AD36/E36,"") | AQ36: =IFERROR(AG36/E36,"") | AR36: =IFERROR(AG36/AF36,"") | AS36: =IFERROR(AH36/AF36,"") | AT36: =IFERROR(AI36/AH36,"") | AU36: =IFERROR(AN36/AH36,"") | BC36: =IFERROR(AG36/AC36,"") | BD36: =IFERROR(AG36/(AC36+AA36),"") | BG36: 2024
A37: PT Gozco Plantations Tbk | B37: 12917 | C37: 12917 | D37: 0 | E37: 12700 | F37: 217 | G37: 2918 | H37: 9782 | I37: 16.58 | K37: 11905 | L37: 1012 | O37: 1 | P37: 90 | AA37: 34068 | AB37: =IFERROR(AA37/AF37,"") | AC37: 189719 | AD37: 189719 | AF37: 210847 | AG37: 48841 | AH37: 9517 | AO37: =IFERROR(AC37/E37,"") | AP37: =IFERROR(AD37/E37,"") | AQ37: =IFERROR(AG37/E37,"") | AR37: =IFERROR(AG37/AF37,"") | AS37: =IFERROR(AH37/AF37,"") | AT37: =IFERROR(AI37/AH37,"") | AU37: =IFERROR(AN37/AH37,"") | AV37: 11917 | AW37: 1 | AX37: 0 | BC37: =IFERROR(AG37/AC37,"") | BD37: =IFERROR(AG37/(AC37+AA37),"") | BE37: 0.2316 | BF37: Reported CPO extraction rate 23.16% in 2022 (vs 22.25% 2021). KER 4.51%. | BG37: 2022
A38: PT Gozco Plantations Tbk | B38: 13114 | C38: 13114 | D38: 0 | E38: 12452 | F38: 662 | G38: 2446 | H38: 10005 | I38: 17.33 | J38: 331 | K38: 12102 | L38: 1012 | O38: 1 | P38: 90 | AA38: 28621 | AB38: =IFERROR(AA38/AF38,"") | AC38: 208937 | AD38: 208937 | AF38: 227025 | AG38: 50310 | AH38: 10532 | AO38: =IFERROR(AC38/E38,"") | AP38: =IFERROR(AD38/E38,"") | AQ38: =IFERROR(AG38/E38,"") | AR38: =IFERROR(AG38/AF38,"") | AS38: =IFERROR(AH38/AF38,"") | AT38: =IFERROR(AI38/AH38,"") | AU38: =IFERROR(AN38/AH38,"") | AV38: 11094 | AW38: 1 | AX38: 0 | BC38: =IFERROR(AG38/AC38,"") | BD38: =IFERROR(AG38/(AC38+AA38),"") | BE38: 0.2216 | BF38: Reported CPO extraction rate 22.16% in 2023 (down from 23.16% in 2022). KER 4.64%. PKS SA mill occupancy ~60% (normal 75%). | BG38: 2023
A39: PT Gozco Plantations Tbk | B39: 15596 | C39: 15200 | D39: 396 | E39: 13939 | F39: 1658 | G39: 4801 | H39: 9137 | I39: 16 | J39: 1203 | K39: 11190 | L39: 4406 | O39: 1 | P39: 90 | AA39: 31296 | AB39: =IFERROR(AA39/AF39,"") | AC39: 225259 | AD39: 225259 | AF39: 206772 | AG39: 43934 | AH39: 9123 | AO39: =IFERROR(AC39/E39,"") | AP39: =IFERROR(AD39/E39,"") | AQ39: =IFERROR(AG39/E39,"") | AR39: =IFERROR(AG39/AF39,"") | AS39: =IFERROR(AH39/AF39,"") | AT39: =IFERROR(AI39/AH39,"") | AU39: =IFERROR(AN39/AH39,"") | AV39: 13117 | AW39: 1 | AX39: 0 | BC39: =IFERROR(AG39/AC39,"") | BD39: =IFERROR(AG39/(AC39+AA39),"") | BE39: 0.2125 | BF39: Reported CPO extraction rate (Rendemen) 21.25% in 2024, down from 22.16% in 2023 due to El Nino drought. KER 4.41%. | BG39: 2024
A40: PT Indo Pureco Pratama Tbk | O40: 1 | AB40: =IFERROR(AA40/AF40,"") | AO40: =IFERROR(AC40/E40,"") | AP40: =IFERROR(AD40/E40,"") | AQ40: =IFERROR(AG40/E40,"") | AR40: =IFERROR(AG40/AF40,"") | AS40: =IFERROR(AH40/AF40,"") | AT40: =IFERROR(AI40/AH40,"") | AU40: =IFERROR(AN40/AH40,"") | BC40: =IFERROR(AG40/AC40,"") | BD40: =IFERROR(AG40/(AC40+AA40),"") | BF40: No palm oil operations. IPPE processes coconut (kelapa), not oil palm (kelapa sawit). No plantation area (buys raw copra from third-party suppliers in Riau, Palembang, Jambi, Tangerang, etc.). Single coconut flesh processing factory in Balingbing, Pagaden Barat, Subang, West Java. Subsidiary ALJ holds 13,587 ha location permit in Katingan, Central Kalimantan for horticultural plantation but subsidiary is pre-operating. 2023 product mix by revenue: Crude Coconut Oil (CCO) 86.08% / Copra Meal (Bungkil Kelapa) 13.92%. All sales domestic (Jakarta, Subang, Bekasi, Central Java, Tangerang); no export sales reported. | BG40: 2023
...

Sheet Financials
A1: Company | B1: Report Year | C1: Revenue (IDR bn) | D1: Gross Profit (IDR bn) | E1: EBITDA Reported (IDR bn) (manual) | F1: EBIT (IDR bn) (manual) | G1: Net Profit (IDR bn) | H1: Profit Attributable to Parent (IDR bn) | I1: Total Assets (IDR bn) | J1: Current Assets (IDR bn) | K1: Non-Current Assets (IDR bn) | L1: Total Liabilities (IDR bn) | M1: Current Liabilities (IDR bn) | N1: Long-Term Liabilities (IDR bn) | O1: Total Equity (IDR bn) | P1: Net Working Capital (IDR bn) [auto] | Q1: Cash & Cash Equivalents (IDR bn) | R1: Gross Debt (IDR bn) | S1: Net Debt Calculated (IDR bn) [auto = R-Q] | T1: CFO (IDR bn) | U1: Capex (IDR bn) (manual; Net Fixed Asset + Bearer Plant Increase, NOT Investing CF) | V1: FCF (IDR bn) [auto] | W1: Shares Outstanding (mn) | X1: EPS (local ccy/share) | Y1: NAV per Share (local ccy/share) | Z1: Interim DPS (local ccy/share) | AA1: Final DPS (local ccy/share) | AB1: Closing Price (local ccy/share) | AC1: Market Cap (IDR bn) [auto] | AD1: Current Ratio (x) [auto] | AE1: Debt / Assets (x) [auto] | AF1: Debt / Equity (x) [auto] | AG1: ROA Reported (%) [auto] | AH1: ROE Reported (%) [auto] | AI1: Net Margin Reported (%) [auto] | AJ1: Gross Margin Reported (%) [auto] | AK1: Financial Risk Note | AL1: Liquidity Note | AM1: Debt Maturity Note | AN1: Covenant Note | AO1: D&A Total (IDR bn) (manual; from Notes) | AP1: EBITDA Calculated (IDR bn) [auto = F+AO] | AQ1: EBITDA Variance (IDR bn) [auto = E-AP] | AR1: Net Debt Reported (IDR bn) (manual) | AS1: Net Debt Variance (IDR bn) [auto = AR-S] | AT1: Net Debt Reported - Definition Note (manual)
A2: PT Astra Agro Lestari Tbk | B2: 2023 | C2: 20745 | D2: 2771 | F2: 1251.22 | G2: 1088 | H2: 1056 | I2: 28846 | J2: 7118 | K2: 21728 | L2: 6280 | M2: 3882 | N2: 2398 | O2: 22566 | P2: =IFERROR(J2-M2,"") | Q2: 2089.51 | R2: 4005.05 | S2: =IFERROR(R2-Q2,"") | T2: 2538.74 | U2: 1236.34 | V2: =IFERROR(T2-U2,"") | W2: 1925 | X2: 549 | Y2: 11724 | Z2: 82 | AA2: 319 | AB2: 7025 | AC2: =IFERROR(W2*AB2/1000,"") | AD2: =IFERROR(J2/M2,"") | AE2: =IFERROR(R2/I2,"") | AF2: =IFERROR(R2/O2,"") | AG2: =IFERROR(G2/I2,"") | AH2: =IFERROR(G2/O2,"") | AI2: =IFERROR(G2/C2,"") | AJ2: =IFERROR(D2/C2,"") | AP2: =IFERROR(IF(AND(NOT(ISNUMBER(F2)),NOT(ISNUMBER(AO2))),"",F2+AO2),"") | AQ2: =IFERROR(IF(OR(NOT(ISNUMBER(E2)),NOT(ISNUMBER(AP2))),"",E2-AP2),"") | AS2: =IFERROR(IF(OR(NOT(ISNUMBER(AR2)),NOT(ISNUMBER(S2))),"",AR2-S2),"")
A3: PT Astra Agro Lestari Tbk | B3: 2024 | C3: 21815 | D3: 3341 | F3: 1658 | G3: 1187 | H3: 1148 | I3: 28793 | J3: 8434 | K3: 20360 | L3: 5591 | M3: 3238 | N3: 2354 | O3: 23202 | P3: =IFERROR(J3-M3,"") | Q3: 3236 | R3: 3190 | S3: =IFERROR(R3-Q3,"") | T3: 3380 | U3: 941 | V3: =IFERROR(T3-U3,"") | W3: 1925 | X3: 596 | Y3: 12055 | Z3: 84 | AA3: 165 | AB3: 6200 | AC3: =IFERROR(W3*AB3/1000,"") | AD3: =IFERROR(J3/M3,"") | AE3: =IFERROR(R3/I3,"") | AF3: =IFERROR(R3/O3,"") | AG3: =IFERROR(G3/I3,"") | AH3: =IFERROR(G3/O3,"") | AI3: =IFERROR(G3/C3,"") | AJ3: =IFERROR(D3/C3,"") | AP3: =IFERROR(IF(AND(NOT(ISNUMBER(F3)),NOT(ISNUMBER(AO3))),"",F3+AO3),"") | AQ3: =IFERROR(IF(OR(NOT(ISNUMBER(E3)),NOT(ISNUMBER(AP3))),"",E3-AP3),"") | AS3: =IFERROR(IF(OR(NOT(ISNUMBER(AR3)),NOT(ISNUMBER(S3))),"",AR3-S3),"") | AT3: Reported gearing <1% in 2024 (2023: 9%); Net debt = Gross debt (Rp3,189.54 bn = 1,689.54 current + 1,500 LT) - cash (Rp3,236 bn) = negative net debt.
A4: PT Astra Agro Lestari Tbk | B4: 2025 | C4: 28654.648 | D4: 4631.429 | F4: 2086.194 | G4: 1471.714 | H4: 1472 | I4: 27047.104 | J4: 8663 | K4: 18384 | L4: 2889.47 | M4: 2000 | N4: 889 | O4: 24157.634 | P4: =IFERROR(J4-M4,"") | Q4: 2755.715 | R4: 0 | S4: =IFERROR(R4-Q4,"") | T4: 4210 | U4: 782 | V4: =IFERROR(T4-U4,"") | W4: 1925 | X4: 765 | Y4: 12551 | Z4: 123 | AB4: 7375 | AC4: =IFERROR(W4*AB4/1000,"") | AD4: =IFERROR(J4/M4,"") | AE4: =IFERROR(R4/I4,"") | AF4: =IFERROR(R4/O4,"") | AG4: =IFERROR(G4/I4,"") | AH4: =IFERROR(G4/O4,"") | AI4: =IFERROR(G4/C4,"") | AJ4: =IFERROR(D4/C4,"") | AP4: =IFERROR(IF(AND(NOT(ISNUMBER(F4)),NOT(ISNUMBER(AO4))),"",F4+AO4),"") | AQ4: =IFERROR(IF(OR(NOT(ISNUMBER(E4)),NOT(ISNUMBER(AP4))),"",E4-AP4),"") | AR4: -2760 | AS4: =IFERROR(IF(OR(NOT(ISNUMBER(AR4)),NOT(ISNUMBER(S4))),"",AR4-S4),"") | AT4: Gearing <1% in 2025 (no bank loans outstanding; all bank loans settled during 2025). Net debt = Gross debt 0 - Cash 2,760 = -Rp2.76 tn (net cash).
A5: PT Andira Agro Tbk | B5: 2022 | C5: 317.86 | D5: 22.78 | F5: -10.54 | G5: -10.79 | H5: -10.79 | I5: 444.21 | J5: 77.82 | K5: 366.39 | L5: 205.52 | M5: 51.32 | N5: 154.2 | O5: 238.69 | P5: =IFERROR(J5-M5,"") | Q5: 15.02 | R5: 166.18 | S5: =IFERROR(R5-Q5,"") | T5: 51.02 | U5: 29.78 | V5: =IFERROR(T5-U5,"") | W5: 9350 | X5: -1.15 | AB5: 50 | AC5: =IFERROR(W5*AB5/1000,"") | AD5: =IFERROR(J5/M5,"") | AE5: =IFERROR(R5/I5,"") | AF5: =IFERROR(R5/O5,"") | AG5: =IFERROR(G5/I5,"") | AH5: =IFERROR(G5/O5,"") | AI5: =IFERROR(G5/C5,"") | AJ5: =IFERROR(D5/C5,"") | AP5: =IFERROR(IF(AND(NOT(ISNUMBER(F5)),NOT(ISNUMBER(AO5))),"",F5+AO5),"") | AQ5: =IFERROR(IF(OR(NOT(ISNUMBER(E5)),NOT(ISNUMBER(AP5))),"",E5-AP5),"") | AS5: =IFERROR(IF(OR(NOT(ISNUMBER(AR5)),NOT(ISNUMBER(S5))),"",AR5-S5),"") | AT5: Net debt approx = Bank loans 166.18 - Cash 15.02 = Rp151.16 bn. D/E 0.861x, D/A 0.463x reported.
